Workbook

Sheet Resumen
B2: Relación materias – simuladores CompanyGame
B3: Universidad El Bosque · Facultad de Ciencias Económicas y Administrativas (FCEA) · Bogotá
B4: Análisis del plan de estudios de 10 programas/mallas frente al catálogo completo de simuladores CompanyGame
I5: Ampliación: CompanyGame + otros simuladores SNC
B6: Programa | C6: N.º de materias | D6: Encaje perfecto | E6: Encaje parcial | F6: No encaja / a desarrollar | G6: % con simulador CG | I6: Materias con otro SNC (perfecto) | J6: Materias con otro SNC (parcial) | K6: Combinado: encaje perfecto | L6: Combinado: encaje parcial | M6: % con simulador (CG + SNC) | N6: Mejora vs. solo CG (p.p.)
B7: Administración de Empresas (Presencial) | C7: =COUNTA('Adm. Empresas (Presencial)'!$B$3:$B$200) -> 66 | D7: =COUNTIF('Adm. Empresas (Presencial)'!$F$3:$F$200,"Encaje perfecto") -> 6 | E7: =COUNTIF('Adm. Empresas (Presencial)'!$F$3:$F$200,"Encaje parcial") -> 4 | F7: =COUNTIF('Adm. Empresas (Presencial)'!$F$3:$F$200,"No encaja") -> 56 | G7: =IFERROR((D7+E7)/C7,0) -> 0.15151515 | I7: =COUNTIF('Adm. Empresas (Presencial)'!$K$3:$K$200,"Encaje perfecto") -> 1 | J7: =COUNTIF('Adm. Empresas (Presencial)'!$K$3:$K$200,"Encaje parcial") -> 1 | K7: =COUNTIF('Adm. Empresas (Presencial)'!$M$3:$M$200,"Encaje perfecto") -> 7 | L7: =COUNTIF('Adm. Empresas (Presencial)'!$M$3:$M$200,"Encaje parcial") -> 4 | M7: =IFERROR((K7+L7)/C7,0) -> 0.16666667 | N7: =(M7-G7)*100 -> 1.5151515
B8: Administración de Empresas (Virtual) | C8: =COUNTA('Adm. Empresas (Virtual)'!$B$3:$B$200) -> 66 | D8: =COUNTIF('Adm. Empresas (Virtual)'!$F$3:$F$200,"Encaje perfecto") -> 6 | E8: =COUNTIF('Adm. Empresas (Virtual)'!$F$3:$F$200,"Encaje parcial") -> 4 | F8: =COUNTIF('Adm. Empresas (Virtual)'!$F$3:$F$200,"No encaja") -> 56 | G8: =IFERROR((D8+E8)/C8,0) -> 0.15151515 | I8: =COUNTIF('Adm. Empresas (Virtual)'!$K$3:$K$200,"Encaje perfecto") -> 1 | J8: =COUNTIF('Adm. Empresas (Virtual)'!$K$3:$K$200,"Encaje parcial") -> 1 | K8: =COUNTIF('Adm. Empresas (Virtual)'!$M$3:$M$200,"Encaje perfecto") -> 7 | L8: =COUNTIF('Adm. Empresas (Virtual)'!$M$3:$M$200,"Encaje parcial") -> 4 | M8: =IFERROR((K8+L8)/C8,0) -> 0.16666667 | N8: =(M8-G8)*100 -> 1.5151515
B9: Administración de Producción y Logística Internacional | C9: =COUNTA('Adm. Producción y Logística'!$B$3:$B$200) -> 65 | D9: =COUNTIF('Adm. Producción y Logística'!$F$3:$F$200,"Encaje perfecto") -> 7 | E9: =COUNTIF('Adm. Producción y Logística'!$F$3:$F$200,"Encaje parcial") -> 2 | F9: =COUNTIF('Adm. Producción y Logística'!$F$3:$F$200,"No encaja") -> 56 | G9: =IFERROR((D9+E9)/C9,0) -> 0.13846154 | I9: =COUNTIF('Adm. Producción y Logística'!$K$3:$K$200,"Encaje perfecto") -> 1 | J9: =COUNTIF('Adm. Producción y Logística'!$K$3:$K$200,"Encaje parcial") -> 1 | K9: =COUNTIF('Adm. Producción y Logística'!$M$3:$M$200,"Encaje perfecto") -> 8 | L9: =COUNTIF('Adm. Producción y Logística'!$M$3:$M$200,"Encaje parcial") -> 2 | M9: =IFERROR((K9+L9)/C9,0) -> 0.15384615 | N9: =(M9-G9)*100 -> 1.5384615
B10: Administración de Negocios Sostenibles (Virtual) | C10: =COUNTA('Adm. Negocios Sostenibles'!$B$3:$B$200) -> 66 | D10: =COUNTIF('Adm. Negocios Sostenibles'!$F$3:$F$200,"Encaje perfecto") -> 7 | E10: =COUNTIF('Adm. Negocios Sostenibles'!$F$3:$F$200,"Encaje parcial") -> 2 | F10: =COUNTIF('Adm. Negocios Sostenibles'!$F$3:$F$200,"No encaja") -> 57 | G10: =IFERROR((D10+E10)/C10,0) -> 0.13636364 | I10: =COUNTIF('Adm. Negocios Sostenibles'!$K$3:$K$200,"Encaje perfecto") -> 2 | J10: =COUNTIF('Adm. Negocios Sostenibles'!$K$3:$K$200,"Encaje parcial") -> 1 | K10: =COUNTIF('Adm. Negocios Sostenibles'!$M$3:$M$200,"Encaje perfecto") -> 9 | L10: =COUNTIF('Adm. Negocios Sostenibles'!$M$3:$M$200,"Encaje parcial") -> 2 | M10: =IFERROR((K10+L10)/C10,0) -> 0.16666667 | N10: =(M10-G10)*100 -> 3.030303
B11: Contaduría Pública | C11: =COUNTA('Contaduría Pública'!$B$3:$B$200) -> 66 | D11: =COUNTIF('Contaduría Pública'!$F$3:$F$200,"Encaje perfecto") -> 6 | E11: =COUNTIF('Contaduría Pública'!$F$3:$F$200,"Encaje parcial") -> 2 | F11: =COUNTIF('Contaduría Pública'!$F$3:$F$200,"No encaja") -> 58 | G11: =IFERROR((D11+E11)/C11,0) -> 0.12121212 | I11: =COUNTIF('Contaduría Pública'!$K$3:$K$200,"Encaje perfecto") -> 2 | J11: =COUNTIF('Contaduría Pública'!$K$3:$K$200,"Encaje parcial") -> 1 | K11: =COUNTIF('Contaduría Pública'!$M$3:$M$200,"Encaje perfecto") -> 8 | L11: =COUNTIF('Contaduría Pública'!$M$3:$M$200,"Encaje parcial") -> 2 | M11: =IFERROR((K11+L11)/C11,0) -> 0.15151515 | N11: =(M11-G11)*100 -> 3.030303
B12: Economía | C12: =COUNTA(Economía!$B$3:$B$200) -> 65 | D12: =COUNTIF(Economía!$F$3:$F$200,"Encaje perfecto") -> 6 | E12: =COUNTIF(Economía!$F$3:$F$200,"Encaje parcial") -> 2 | F12: =COUNTIF(Economía!$F$3:$F$200,"No encaja") -> 57 | G12: =IFERROR((D12+E12)/C12,0) -> 0.12307692 | I12: =COUNTIF(Economía!$K$3:$K$200,"Encaje perfecto") -> 0 | J12: =COUNTIF(Economía!$K$3:$K$200,"Encaje parcial") -> 1 | K12: =COUNTIF(Economía!$M$3:$M$200,"Encaje perfecto") -> 6 | L12: =COUNTIF(Economía!$M$3:$M$200,"Encaje parcial") -> 2 | M12: =IFERROR((K12+L12)/C12,0) -> 0.12307692 | N12: =(M12-G12)*100 -> 0
B13: Finanzas | C13: =COUNTA(Finanzas!$B$3:$B$200) -> 66 | D13: =COUNTIF(Finanzas!$F$3:$F$200,"Encaje perfecto") -> 8 | E13: =COUNTIF(Finanzas!$F$3:$F$200,"Encaje parcial") -> 3 | F13: =COUNTIF(Finanzas!$F$3:$F$200,"No encaja") -> 55 | G13: =IFERROR((D13+E13)/C13,0) -> 0.16666667 | I13: =COUNTIF(Finanzas!$K$3:$K$200,"Encaje perfecto") -> 0 | J13: =COUNTIF(Finanzas!$K$3:$K$200,"Encaje parcial") -> 2 | K13: =COUNTIF(Finanzas!$M$3:$M$200,"Encaje perfecto") -> 8 | L13: =COUNTIF(Finanzas!$M$3:$M$200,"Encaje parcial") -> 4 | M13: =IFERROR((K13+L13)/C13,0) -> 0.18181818 | N13: =(M13-G13)*100 -> 1.5151515
B14: Marketing y Transformación Digital | C14: =COUNTA('Marketing y Transf. Digital'!$B$3:$B$200) -> 66 | D14: =COUNTIF('Marketing y Transf. Digital'!$F$3:$F$200,"Encaje perfecto") -> 9 | E14: =COUNTIF('Marketing y Transf. Digital'!$F$3:$F$200,"Encaje parcial") -> 3 | F14: =COUNTIF('Marketing y Transf. Digital'!$F$3:$F$200,"No encaja") -> 54 | G14: =IFERROR((D14+E14)/C14,0) -> 0.18181818 | I14: =COUNTIF('Marketing y Transf. Digital'!$K$3:$K$200,"Encaje perfecto") -> 1 | J14: =COUNTIF('Marketing y Transf. Digital'!$K$3:$K$200,"Encaje parcial") -> 1 | K14: =COUNTIF('Marketing y Transf. Digital'!$M$3:$M$200,"Encaje perfecto") -> 10 | L14: =COUNTIF('Marketing y Transf. Digital'!$M$3:$M$200,"Encaje parcial") -> 4 | M14: =IFERROR((K14+L14)/C14,0) -> 0.21212121 | N14: =(M14-G14)*100 -> 3.030303
B15: Negocios Internacionales (Presencial) | C15: =COUNTA('Negocios Internac. (Presenc.)'!$B$3:$B$200) -> 64 | D15: =COUNTIF('Negocios Internac. (Presenc.)'!$F$3:$F$200,"Encaje perfecto") -> 9 | E15: =COUNTIF('Negocios Internac. (Presenc.)'!$F$3:$F$200,"Encaje parcial") -> 3 | F15: =COUNTIF('Negocios Internac. (Presenc.)'!$F$3:$F$200,"No encaja") -> 52 | G15: =IFERROR((D15+E15)/C15,0) -> 0.1875 | I15: =COUNTIF('Negocios Internac. (Presenc.)'!$K$3:$K$200,"Encaje perfecto") -> 0 | J15: =COUNTIF('Negocios Internac. (Presenc.)'!$K$3:$K$200,"Encaje parcial") -> 3 | K15: =COUNTIF('Negocios Internac. (Presenc.)'!$M$3:$M$200,"Encaje perfecto") -> 9 | L15: =COUNTIF('Negocios Internac. (Presenc.)'!$M$3:$M$200,"Encaje parcial") -> 6 | M15: =IFERROR((K15+L15)/C15,0) -> 0.234375 | N15: =(M15-G15)*100 -> 4.6875
B16: Negocios Internacionales (Virtual) | C16: =COUNTA('Negocios Internac. (Virtual)'!$B$3:$B$200) -> 64 | D16: =COUNTIF('Negocios Internac. (Virtual)'!$F$3:$F$200,"Encaje perfecto") -> 9 | E16: =COUNTIF('Negocios Internac. (Virtual)'!$F$3:$F$200,"Encaje parcial") -> 3 | F16: =COUNTIF('Negocios Internac. (Virtual)'!$F$3:$F$200,"No encaja") -> 52 | G16: =IFERROR((D16+E16)/C16,0) -> 0.1875 | I16: =COUNTIF('Negocios Internac. (Virtual)'!$K$3:$K$200,"Encaje perfecto") -> 0 | J16: =COUNTIF('Negocios Internac. (Virtual)'!$K$3:$K$200,"Encaje parcial") -> 3 | K16: =COUNTIF('Negocios Internac. (Virtual)'!$M$3:$M$200,"Encaje perfecto") -> 9 | L16: =COUNTIF('Negocios Internac. (Virtual)'!$M$3:$M$200,"Encaje parcial") -> 6 | M16: =IFERROR((K16+L16)/C16,0) -> 0.234375 | N16: =(M16-G16)*100 -> 4.6875
B17: TOTAL | C17: =SUM(C7:C16) -> 654 | D17: =SUM(D7:D16) -> 73 | E17: =SUM(E7:E16) -> 28 | F17: =SUM(F7:F16) -> 553 | G17: =IFERROR((D17+E17)/C17,0) -> 0.15443425 | I17: =SUM(I7:I16) -> 8 | J17: =SUM(J7:J16) -> 15 | K17: =SUM(K7:K16) -> 81 | L17: =SUM(L7:L16) -> 36 | M17: =IFERROR((K17+L17)/C17,0) -> 0.17889908 | N17: =(M17-G17)*100 -> 2.4464832
B19: Convención de la columna 'Grado de ajuste':
B20: Encaje perfecto | C20: Un simulador CompanyGame cubre directamente la materia
B21: Encaje parcial | C21: Un simulador CG cubre parte de la materia; se sugiere complementar/desarrollar
B22: No encaja | C22: Ningún simulador CG aplica; se propone el tipo de simulador a desarrollar
B24: Notas metodológicas
B25: · Mallas tomadas de los 10 PDF 'Plan de estudios' oficiales de la Facultad de Ciencias Económicas y
B26: Administrativas (FCEA) de la Universidad El Bosque, entregados por Paula: Administración de Empresas
B27: (Presencial y Virtual), Administración de Producción y Logística Internacional, Administración de
B28: Negocios Sostenibles (Virtual), Contaduría Pública, Economía, Finanzas, Marketing y Transformación
B29: Digital, y Negocios Internacionales (Presencial y Virtual).
B30: · Los 10 programas comparten un mismo modelo curricular de 8 semestres / 144 créditos, con 3 bloques:
B31: Ciclo de Fundamentación (semestres I-II, IDÉNTICO en los 10 programas: Contabilidad General/de
B32: Costos, Principios de Administración/Procesos Administrativos, Principios de Economía/Medición
B33: Económica, Fundamentos de las Finanzas/Matemáticas Financieras, Logística Internacional/Dinámicas de
B34: Cadenas de Valor Globales, Teoría de los Negocios Internacionales/Geopolítica, Fundamentos de
B35: Marketing/Investigación de Mercados, Responsabilidad Social/Sostenibilidad y Empresa), Ciclo de
... B95: equivalente tampoco en los simuladores adicionales.

Sheet Catálogo CompanyGame
A2: Catálogo CompanyGame
A3: 41 simuladores en 8 categorías (companygame.com)
A4: Categoría | B4: Simulador | C4: Nivel | D4: Descripción
A5: Negocios y Estrategia | B5: T-Shirt | C5: N1-2 | D5: Introducción a la gestión empresarial (sector textil)
B6: Sunny Day | C6: N1-2 | D6: Introducción a la gestión; visión global (bebidas/consumo)
B7: Energy&Co | C7: N1-2 | D7: Introducción a la gestión empresarial (sector energético)
B8: Business21 | C8: N3-4 | D8: Dirección general intermedia; visión integral
B9: Business Global | C9: N5 | D9: Dirección general avanzada; simulación gerencial integral
B10: Business Strategy | C10: N6-7 | D10: Estrategia empresarial (executive/posgrado)
A11: Marketing y Ventas | B11: MarketGame | C11: N1-2 | D11: Introducción al marketing y decisiones comerciales
B12: Coffee Time | C12: N1-2 | D12: Marketing y retail (sector cafetería)
B13: Food Company | C13: N3-4 | D13: Marketing estratégico sector alimentos
B14: SalesManager | C14: N3-4 | D14: Gestión de la fuerza de ventas
B15: TechCompany | C15: N5 | D15: Marketing sector tecnológico
B16: FOCUS | C16: N5 | D16: Investigación de mercados y marketing estratégico
B17: GlobalMarket | C17: N6-7 | D17: Marketing global (executive)
A18: Finanzas y Banca | B18: ContaTrainer | C18: N1-2 | D18: Apuntes y registros contables; contabilidad básica
B19: Advisor Jr. | C19: N1-2 / N3-4 | D19: Asesoría financiera y productos financieros
B20: Corbatul | C20: N3-4 | D20: Gestión financiera empresarial
B21: Trading (Real Market Stocks) | C21: N3-4 | D21: Bolsa y mercados de capitales (acciones reales)
B22: Bankgame | C22: N5 | D22: Gestión de oficina bancaria
B23: BankCompany | C23: N6-7 | D23: Estrategia y dirección bancaria (executive)
A24: Emprendimiento | B24: Fitness Gym | C24: N3-4 | D24: Plan de negocio / creación de empresa (gimnasio)
B25: Luxe Atelier | C25: N5 | D25: Emprendimiento (taller de moda)
B26: Business Chef | C26: N5 | D26: Emprendimiento y gestión de restaurante
B27: Fitness Gym Executive | C27: N6-7 | D27: Emprendimiento avanzado y gestión de proyecto
A28: Business Transformation | B28: InnovaTech | C28: N3-4 | D28: Innovación y transformación digital
B29: Inter Pyme | C29: N3-4 | D29: Internacionalización de pymes
B30: Avocado Expand | C30: N3-4 | D30: Internacionalización / expansión exportadora
B31: Transforma | C31: N5 | D31: Transformación empresarial
B32: Business Advance | C32: N5 | D32: Negocio digital / e-commerce
B33: Global 2020 | C33: N6-7 | D33: Globalización y dirección global
B34: Global 2030 | C34: N6-7 | D34: Globalización con enfoque de sostenibilidad
A35: HORECA / Hospitalidad y Servicios | B35: Hotel Game | C35: N1-2 | D35: Introducción a la gestión hotelera
B36: Hotel Virtual | C36: N1-2 | D36: Operación hotelera
B37: Casa Guadalupe | C37: N3-4 | D37: Restauración y hospitalidad (F&B)
B38: Five Stars | C38: N5 | D38: Gestión hotelera avanzada / servicio
B39: Innova Hotel | C39: N6-7 | D39: Innovación hotelera
B40: Hotel Company | C40: N6-7 | D40: Dirección hotelera (executive)
A41: ESG Management | B41: Sweet Berries | C41: N1-2 | D41: Negocio sostenible introductorio (agro)
...

Sheet Catálogo otros SNC
A2: Otros simuladores de Simuladores de Negocios Colombia (SNC)
A3: Complementan el catálogo CompanyGame. Nivel expresado como equivalencia aproximada a la escala CG (N1-2 Intro · N3-4 Avanzado · N5 Graduate · N6-7 Postgrado/Executive).
A4: Línea / proveedor | B4: Simulador | C4: Nivel sugerido | D4: Descripción | E4: Materias típicas donde encaja | F4: Estado de la información
A5: SimVenture | B5: SimVenture Evolution | C5: Intro–Intermedio (≈N1-4) | D5: Simulador de gestión integral de una pequeña empresa: el estudiante dirige el negocio hasta 10 años simulados (40 trimestres) con decisiones en ventas y marketing, finanzas, operaciones, I+D y organización. Trata el tiempo del emprendedor como recurso escaso junto al capital. | E5: Emprendimiento, fundamentos de administración/finanzas, gestión empresarial integral, cursos de simulación gerencial. | F5: Información pública (simventure.com)
A6: SimVenture | B6: SimVenture Validate | C6: Intro (≈N1-2) | D6: Plataforma para idear, mapear, testear y presentar ideas de negocio: Business Model Canvas con componente de sostenibilidad + metodología lean startup para validar supuestos; incluye 8 casos reales y portafolio digital. | E6: Emprendimiento, innovación/creatividad, modelos de negocio (incl. sostenibles), design thinking. | F6: Información pública (simventure.com)
A7: Simulation Powered Learning | B7: SimProject | C7: Intermedio–Avanzado (≈N3-5) | D7: El estudiante asume el rol de gerente de proyecto: planifica y ejecuta un proyecto gestionando alcance, cronograma, asignación de personal, presupuesto y riesgos; alineado a PMBOK. | E7: Project Management, gerencia de proyectos, formulación de proyectos (fase de planificación). | F7: Información pública (simulationpl.com)
A8: Simulation Powered Learning | B8: SimAgile | C8: Intermedio–Avanzado (≈N3-5) | D8: El estudiante asume el rol de Scrum Master: gestiona backlog, sprints y equipo, y observa el efecto de sus decisiones en la velocidad y el valor entregado. | E8: Gestión ágil, Project Management (enfoque ágil), transformación digital, desarrollo de producto. | F8: Información pública (simulationpl.com)
A9: SNC – nuevo desarrollo | B9: Auditek | C9: Por confirmar (nuevo desarrollo) | D9: Simulador de auditoría / revisoría fiscal (nuevo desarrollo de SNC). Supuesto de trabajo: simula un encargo de auditoría (planeación, evaluación de control interno, pruebas, hallazgos y dictamen). | E9: Revisoría Fiscal, Auditoría financiera, Control interno. | F9: Sin ficha pública — validar alcance y nivel con SNC
A10: SNC – nuevo desarrollo | B10: RentaSim | C10: Por confirmar (nuevo desarrollo) | D10: Simulador tributario (nuevo desarrollo de SNC). Supuesto de trabajo: simula la depuración y declaración del impuesto de renta en Colombia. | E10: Tributaria I/II, Fundamentos de Derecho Tributario, Planeación Fiscal. | F10: Sin ficha pública — validar alcance y nivel con SNC

Sheet Adm. Empresas (Presencial)
A1: Administración de Empresas · Presencial
A2: Semestre | B2: Materia | C2: Área temática | D2: Simulador CompanyGame que encaja | E2: Nivel CG | F2: Grado de ajuste | G2: Tipo de simulador a desarrollar (si no encaja / parcial) | H2: Observación | I2: Otro simulador SNC que encaja | J2: Nivel sugerido | K2: Grado de ajuste (otro SNC) | L2: Observación / uso sugerido (otro SNC) | M2: Cobertura combinada (CG + otro SNC)
A3: 1 | B3: Contabilidad General | C3: Contabilidad | D3: ContaTrainer | E3: N1-2 | F3: Encaje perfecto | I3: — | J3: — | K3: — | M3: =IF(OR(F3="Encaje perfecto",K3="Encaje perfecto"),"Encaje perfecto",IF(OR(F3="Encaje parcial",K3="Encaje parcial"),"Encaje parcial","No encaja")) -> Encaje perfecto
A4: 1 | B4: Principios de Administración y Organizaciones | C4: Administración | D4: T-Shirt | E4: N1-2 | F4: Encaje perfecto | I4: — | J4: — | K4: — | M4: =IF(OR(F4="Encaje perfecto",K4="Encaje perfecto"),"Encaje perfecto",IF(OR(F4="Encaje parcial",K4="Encaje parcial"),"Encaje parcial","No encaja")) -> Encaje perfecto
A5: 1 | B5: Principios de Economía | C5: Formación general / sin equivalente en el catálogo | D5: — | E5: — | F5: No encaja | I5: — | J5: — | K5: — | M5: =IF(OR(F5="Encaje perfecto",K5="Encaje perfecto"),"Encaje perfecto",IF(OR(F5="Encaje parcial",K5="Encaje parcial"),"Encaje parcial","No encaja")) -> No encaja
A6: 1 | B6: Fundamentos de las Finanzas Empresariales | C6: Finanzas | D6: — | E6: — | F6: No encaja | I6: — | J6: — | K6: — | M6: =IF(OR(F6="Encaje perfecto",K6="Encaje perfecto"),"Encaje perfecto",IF(OR(F6="Encaje parcial",K6="Encaje parcial"),"Encaje parcial","No encaja")) -> No encaja
A7: 1 | B7: Logística Internacional | C7: Formación general / sin equivalente en el catálogo | D7: — | E7: — | F7: No encaja | I7: — | J7: — | K7: — | M7: =IF(OR(F7="Encaje perfecto",K7="Encaje perfecto"),"Encaje perfecto",IF(OR(F7="Encaje parcial",K7="Encaje parcial"),"Encaje parcial","No encaja")) -> No encaja
A8: 1 | B8: Teoría de los Negocios Internacionales | C8: Internacional | D8: — | E8: — | F8: No encaja | I8: — | J8: — | K8: — | M8: =IF(OR(F8="Encaje perfecto",K8="Encaje perfecto"),"Encaje perfecto",IF(OR(F8="Encaje parcial",K8="Encaje parcial"),"Encaje parcial","No encaja")) -> No encaja
A9: 1 | B9: Fundamentos de Marketing y Transformación Digital | C9: Marketing | D9: CoffeeTime | E9: N1-2 | F9: Encaje parcial | I9: — | J9: — | K9: — | M9: =IF(OR(F9="Encaje perfecto",K9="Encaje perfecto"),"Encaje perfecto",IF(OR(F9="Encaje parcial",K9="Encaje parcial"),"Encaje parcial","No encaja")) -> Encaje parcial
A10: 1 | B10: Responsabilidad Social Empresarial | C10: Sostenibilidad | D10: — | E10: — | F10: No encaja | I10: — | J10: — | K10: — | M10: =IF(OR(F10="Encaje perfecto",K10="Encaje perfecto"),"Encaje perfecto",IF(OR(F10="Encaje parcial",K10="Encaje parcial"),"Encaje parcial","No encaja")) -> No encaja
A11: 1 | B11: Pensamiento Crítico y Comunicación Efectiva | C11: Formación general / sin equivalente en el catálogo | D11: — | E11: — | F11: No encaja | I11: — | J11: — | K11: — | M11: =IF(OR(F11="Encaje perfecto",K11="Encaje perfecto"),"Encaje perfecto",IF(OR(F11="Encaje parcial",K11="Encaje parcial"),"Encaje parcial","No encaja")) -> No encaja
A12: 2 | B12: Contabilidad de Costos | C12: Formación general / sin equivalente en el catálogo | D12: — | E12: — | F12: No encaja | I12: — | J12: — | K12: — | M12: =IF(OR(F12="Encaje perfecto",K12="Encaje perfecto"),"Encaje perfecto",IF(OR(F12="Encaje parcial",K12="Encaje parcial"),"Encaje parcial","No encaja")) -> No encaja
A13: 2 | B13: Procesos Administrativos | C13: Administración | D13: Energy&Co | E13: N1-2 | F13: Encaje perfecto | I13: — | J13: — | K13: — | M13: =IF(OR(F13="Encaje perfecto",K13="Encaje perfecto"),"Encaje perfecto",IF(OR(F13="Encaje parcial",K13="Encaje parcial"),"Encaje parcial","No encaja")) -> Encaje perfecto
A14: 2 | B14: Medición Económica | C14: Formación general / sin equivalente en el catálogo | D14: — | E14: — | F14: No encaja | I14: — | J14: — | K14: — | M14: =IF(OR(F14="Encaje perfecto",K14="Encaje perfecto"),"Encaje perfecto",IF(OR(F14="Encaje parcial",K14="Encaje parcial"),"Encaje parcial","No encaja")) -> No encaja
... A25: 3 | B25: Taller de Negociación y Argumentación | C25: Formación general / sin equivalente en el catálogo | D25: — | E25: — | F25: No encaja | I25: — | J25: — | K25: — | M25: =IF(OR(F25="Encaje perfecto",K25="Encaje perfecto"),"Encaje perfecto",IF(OR(F25="Encaje parcial",K25="Encaje parcial"),"Encaje parcial","No encaja")) -> No encaja
A26: 3 | B26: Electiva I | C26: Electiva | D26: — | E26: — | F26: No encaja | G26: Contenido variable según la línea elegida; evaluar caso a caso | I26: — | J26: — | K26: — | M26: =IF(OR(F26="Encaje perfecto",K26="Encaje perfecto"),"Encaje perfecto",IF(OR(F26="Encaje parcial",K26="Encaje parcial"),"Encaje parcial","No encaja")) -> No encaja
A27: 3 | B27: Electiva II | C27: Electiva | D27: — | E27: — | F27: No encaja | G27: Contenido variable según la línea elegida; evaluar caso a caso | I27: — | J27: — | K27: — | M27: =IF(OR(F27="Encaje perfecto",K27="Encaje perfecto"),"Encaje perfecto",IF(OR(F27="Encaje parcial",K27="Encaje parcial"),"Encaje parcial","No encaja")) -> No encaja
A28: 4 | B28: Macroeconomía | C28: Economía | D28: — | E28: — | F28: No encaja | I28: — | J28: — | K28: — | M28: =IF(OR(F28="Encaje perfecto",K28="Encaje perfecto"),"Encaje perfecto",IF(OR(F28="Encaje parcial",K28="Encaje parcial"),"Encaje parcial","No encaja")) -> No encaja
A29: 4 | B29: Derecho Laboral y Gestión de Riesgos Organizacionales | C29: Jurídica | D29: — | E29: — | F29: No encaja | I29: — | J29: — | K29: — | M29: =IF(OR(F29="Encaje perfecto",K29="Encaje perfecto"),"Encaje perfecto",IF(OR(F29="Encaje parcial",K29="Encaje parcial"),"Encaje parcial","No encaja")) -> No encaja
A30: 4 | B30: Modelos Organizacionales y Empresariales I | C30: Administración | D30: — | E30: — | F30: No encaja | I30: — | J30: — | K30: — | M30: =IF(OR(F30="Encaje perfecto",K30="Encaje perfecto"),"Encaje perfecto",IF(OR(F30="Encaje parcial",K30="Encaje parcial"),"Encaje parcial","No encaja")) -> No encaja
A31: 4 | B31: Total Quality Management and Innovation | C31: Innovación | D31: — | E31: — | F31: No encaja | I31: — | J31: — | K31: — | M31: =IF(OR(F31="Encaje perfecto",K31="Encaje perfecto"),"Encaje perfecto",IF(OR(F31="Encaje parcial",K31="Encaje parcial"),"Encaje parcial","No encaja")) -> No encaja
A32: 4 | B32: Instituciones Políticas y Competencias Ciudadanas | C32: Formación general / sin equivalente en el catálogo | D32: — | E32: — | F32: No encaja | I32: — | J32: — | K32: — | M32: =IF(OR(F32="Encaje perfecto",K32="Encaje perfecto"),"Encaje perfecto",IF(OR(F32="Encaje parcial",K32="Encaje parcial"),"Encaje parcial","No encaja")) -> No encaja
A33: 4 | B33: Idiomas II | C33: Idiomas | D33: — | E33: — | F33: No encaja | I33: — | J33: — | K33: — | M33: =IF(OR(F33="Encaje perfecto",K33="Encaje perfecto"),"Encaje perfecto",IF(OR(F33="Encaje parcial",K33="Encaje parcial"),"Encaje parcial","No encaja")) -> No encaja
A34: 4 | B34: Bioética y Toma de Decisiones Gerenciales | C34: Formación general / sin equivalente en el catálogo | D34: — | E34: — | F34: No encaja | I34: — | J34: — | K34: — | M34: =IF(OR(F34="Encaje perfecto",K34="Encaje perfecto"),"Encaje perfecto",IF(OR(F34="Encaje parcial",K34="Encaje parcial"),"Encaje parcial","No encaja")) -> No encaja
A35: 4 | B35: Electiva III | C35: Electiva | D35: — | E35: — | F35: No encaja | G35: Contenido variable según la línea elegida; evaluar caso a caso | I35: — | J35: — | K35: — | M35: =IF(OR(F35="Encaje perfecto",K35="Encaje perfecto"),"Encaje perfecto",IF(OR(F35="Encaje parcial",K35="Encaje parcial"),"Encaje parcial","No encaja")) -> No encaja
A36: 5 | B36: Economía Colombiana | C36: Economía | D36: — | E36: — | F36: No encaja | I36: — | J36: — | K36: — | M36: =IF(OR(F36="Encaje perfecto",K36="Encaje perfecto"),"Encaje perfecto",IF(OR(F36="Encaje parcial",K36="Encaje parcial"),"Encaje parcial","No encaja")) -> No encaja
A37: 5 | B37: Finanzas Corporativas | C37: Finanzas | D37: Corbatul | E37: N3-4 | F37: Encaje perfecto | I37: — | J37: — | K37: — | M37: =IF(OR(F37="Encaje perfecto",K37="Encaje perfecto"),"Encaje perfecto",IF(OR(F37="Encaje parcial",K37="Encaje parcial"),"Encaje parcial","No encaja")) -> Encaje perfecto
A38: 5 | B38: Modelos Organizacionales y Empresariales II | C38: Administración | D38: — | E38: — | F38: No encaja | I38: — | J38: — | K38: — | M38: =IF(OR(F38="Encaje perfecto",K38="Encaje perfecto"),"Encaje perfecto",IF(OR(F38="Encaje parcial",K38="Encaje parcial"),"Encaje parcial","No encaja")) -> No encaja
A39: 5 | B39: Production Management | C39: Operaciones | D39: Milk Factory | E39: N5 | F39: Encaje perfecto | I39: — | J39: — | K39: — | M39: =IF(OR(F39="Encaje perfecto",K39="Encaje perfecto"),"Encaje perfecto",IF(OR(F39="Encaje parcial",K39="Encaje parcial"),"Encaje parcial","No encaja")) -> Encaje perfecto
A40: 5 | B40: Formulación y Evaluación de Proyectos | C40: Finanzas/Proyectos | D40: — | E40: — | F40: No encaja | G40: Simulador de evaluación financiera de proyectos (VPN, TIR, flujo de caja proyectado) | I40: — | J40: — | K40: — | M40: =IF(OR(F40="Encaje perfecto",K40="Encaje perfecto"),"Encaje perfecto",IF(OR(F40="Encaje parcial",K40="Encaje parcial"),"Encaje parcial","No encaja")) -> No encaja
A41: 5 | B41: Derecho Internacional de los Negocios | C41: Formación general / sin equivalente en el catálogo | D41: — | E41: — | F41: No encaja | I41: — | J41: — | K41: — | M41: =IF(OR(F41="Encaje perfecto",K41="Encaje perfecto"),"Encaje perfecto",IF(OR(F41="Encaje parcial",K41="Encaje parcial"),"Encaje parcial","No encaja")) -> No encaja
A42: 5 | B42: Idiomas III | C42: Idiomas | D42: — | E42: — | F42: No encaja | I42: — | J42: — | K42: — | M42: =IF(OR(F42="Encaje perfecto",K42="Encaje perfecto"),"Encaje perfecto",IF(OR(F42="Encaje parcial",K42="Encaje parcial"),"Encaje parcial","No encaja")) -> No encaja
A43: 5 | B43: Emprendimiento y Creación de Empresa | C43: Emprendimiento | D43: Fitness Gym | E43: N3-4 | F43: Encaje parcial | I43: SimVenture Validate | J43: Intro (≈N1-2) | K43: Encaje parcial | L43: Cubre el componente de modelos de negocio (Business Model Canvas + validación lean). No cubre estructuras ni diseño organizacional. Validate también sirve como complemento en Emprendimiento y Creación de Empresa. | M43: =IF(OR(F43="Encaje perfecto",K43="Encaje perfecto"),"Encaje perfecto",IF(OR(F43="Encaje parcial",K43="Encaje parcial"),"Encaje parcial","No encaja")) -> Encaje parcial
A44: 5 | B44: Electiva IV | C44: Electiva | D44: — | E44: — | F44: No encaja | G44: Contenido variable según la línea elegida; evaluar caso a caso | I44: — | J44: — | K44: — | M44: =IF(OR(F44="Encaje perfecto",K44="Encaje perfecto"),"Encaje perfecto",IF(OR(F44="Encaje parcial",K44="Encaje parcial"),"Encaje parcial","No encaja")) -> No encaja
A45: 6 | B45: International Economy | C45: Economía | D45: — | E45: — | F45: No encaja | I45: — | J45: — | K45: — | M45: =IF(OR(F45="Encaje perfecto",K45="Encaje perfecto"),"Encaje perfecto",IF(OR(F45="Encaje parcial",K45="Encaje parcial"),"Encaje parcial","No encaja")) -> No encaja
A46: 6 | B46: Finanzas Públicas | C46: Finanzas Públicas / Presupuesto | D46: — | E46: — | F46: No encaja | I46: — | J46: — | K46: — | M46: =IF(OR(F46="Encaje perfecto",K46="Encaje perfecto"),"Encaje perfecto",IF(OR(F46="Encaje parcial",K46="Encaje parcial"),"Encaje parcial","No encaja")) -> No encaja
A47: 6 | B47: Strategic Planning and Managerial Prospective | C47: Estrategia | D47: — | E47: — | F47: No encaja | I47: — | J47: — | K47: — | M47: =IF(OR(F47="Encaje perfecto",K47="Encaje perfecto"),"Encaje perfecto",IF(OR(F47="Encaje parcial",K47="Encaje parcial"),"Encaje parcial","No encaja")) -> No encaja
A48: 6 | B48: Advanced Digital Processing | C48: Digital | D48: Business Advance | E48: N5 | F48: Encaje parcial | I48: — | J48: — | K48: — | M48: =IF(OR(F48="Encaje perfecto",K48="Encaje perfecto"),"Encaje perfecto",IF(OR(F48="Encaje parcial",K48="Encaje parcial"),"Encaje parcial","No encaja")) -> Encaje parcial
A49: 6 | B49: Teoria y Juegos Gerenciales | C49: Gerencia | D49: Global 2020 | E49: N6-7 | F49: Encaje perfecto | I49: — | J49: — | K49: — | M49: =IF(OR(F49="Encaje perfecto",K49="Encaje perfecto"),"Encaje perfecto",IF(OR(F49="Encaje parcial",K49="Encaje parcial"),"Encaje parcial","No encaja")) -> Encaje perfecto
A50: 6 | B50: Administración Pública | C50: Administración Pública | D50: — | E50: — | F50: No encaja | I50: — | J50: — | K50: — | M50: =IF(OR(F50="Encaje perfecto",K50="Encaje perfecto"),"Encaje perfecto",IF(OR(F50="Encaje parcial",K50="Encaje parcial"),"Encaje parcial","No encaja")) -> No encaja
...

Sheet Adm. Empresas (Virtual)
A1: Administración de Empresas · Virtual
A2: Semestre | B2: Materia | C2: Área temática | D2: Simulador CompanyGame que encaja | E2: Nivel CG | F2: Grado de ajuste | G2: Tipo de simulador a desarrollar (si no encaja / parcial) | H2: Observación | I2: Otro simulador SNC que encaja | J2: Nivel sugerido | K2: Grado de ajuste (otro SNC) | L2: Observación / uso sugerido (otro SNC) | M2: Cobertura combinada (CG + otro SNC)
A3: 1 | B3: Contabilidad General | C3: Contabilidad | D3: ContaTrainer | E3: N1-2 | F3: Encaje perfecto | I3: — | J3: — | K3: — | M3: =IF(OR(F3="Encaje perfecto",K3="Encaje perfecto"),"Encaje perfecto",IF(OR(F3="Encaje parcial",K3="Encaje parcial"),"Encaje parcial","No encaja")) -> Encaje perfecto
A4: 1 | B4: Principios de Administración y Organizaciones | C4: Administración | D4: T-Shirt | E4: N1-2 | F4: Encaje perfecto | I4: — | J4: — | K4: — | M4: =IF(OR(F4="Encaje perfecto",K4="Encaje perfecto"),"Encaje perfecto",IF(OR(F4="Encaje parcial",K4="Encaje parcial"),"Encaje parcial","No encaja")) -> Encaje perfecto
A5: 1 | B5: Principios de Economía | C5: Formación general / sin equivalente en el catálogo | D5: — | E5: — | F5: No encaja | I5: — | J5: — | K5: — | M5: =IF(OR(F5="Encaje perfecto",K5="Encaje perfecto"),"Encaje perfecto",IF(OR(F5="Encaje parcial",K5="Encaje parcial"),"Encaje parcial","No encaja")) -> No encaja
A6: 1 | B6: Fundamentos de las Finanzas Empresariales | C6: Finanzas | D6: — | E6: — | F6: No encaja | M6: =IF(OR(F6="Encaje perfecto",K6="Encaje perfecto"),"Encaje perfecto",IF(OR(F6="Encaje parcial",K6="Encaje parcial"),"Encaje parcial","No encaja")) -> No encaja
A7: 1 | B7: Logística Internacional | C7: Formación general / sin equivalente en el catálogo | D7: — | E7: — | F7: No encaja | I7: — | J7: — | K7: — | M7: =IF(OR(F7="Encaje perfecto",K7="Encaje perfecto"),"Encaje perfecto",IF(OR(F7="Encaje parcial",K7="Encaje parcial"),"Encaje parcial","No encaja")) -> No encaja
A8: 1 | B8: Teoría de los Negocios Internacionales | C8: Internacional | D8: — | E8: — | F8: No encaja | I8: — | J8: — | K8: — | M8: =IF(OR(F8="Encaje perfecto",K8="Encaje perfecto"),"Encaje perfecto",IF(OR(F8="Encaje parcial",K8="Encaje parcial"),"Encaje parcial","No encaja")) -> No encaja
A9: 1 | B9: Fundamentos de Marketing y Transformación Digital | C9: Marketing | D9: CoffeeTime | E9: N1-2 | F9: Encaje parcial | I9: — | J9: — | K9: — | M9: =IF(OR(F9="Encaje perfecto",K9="Encaje perfecto"),"Encaje perfecto",IF(OR(F9="Encaje parcial",K9="Encaje parcial"),"Encaje parcial","No encaja")) -> Encaje parcial
A10: 1 | B10: Responsabilidad Social Empresarial | C10: Sostenibilidad | D10: — | E10: — | F10: No encaja | I10: — | J10: — | K10: — | M10: =IF(OR(F10="Encaje perfecto",K10="Encaje perfecto"),"Encaje perfecto",IF(OR(F10="Encaje parcial",K10="Encaje parcial"),"Encaje parcial","No encaja")) -> No encaja
A11: 1 | B11: Pensamiento Crítico y Comunicación Efectiva | C11: Formación general / sin equivalente en el catálogo | D11: — | E11: — | F11: No encaja | I11: — | J11: — | K11: — | M11: =IF(OR(F11="Encaje perfecto",K11="Encaje perfecto"),"Encaje perfecto",IF(OR(F11="Encaje parcial",K11="Encaje parcial"),"Encaje parcial","No encaja")) -> No encaja
A12: 2 | B12: Contabilidad de Costos | C12: Formación general / sin equivalente en el catálogo | D12: — | E12: — | F12: No encaja | I12: — | J12: — | K12: — | M12: =IF(OR(F12="Encaje perfecto",K12="Encaje perfecto"),"Encaje perfecto",IF(OR(F12="Encaje parcial",K12="Encaje parcial"),"Encaje parcial","No encaja")) -> No encaja
A13: 2 | B13: Procesos Administrativos | C13: Administración | D13: Energy&Co | E13: N1-2 | F13: Encaje perfecto | I13: — | J13: — | K13: — | M13: =IF(OR(F13="Encaje perfecto",K13="Encaje perfecto"),"Encaje perfecto",IF(OR(F13="Encaje parcial",K13="Encaje parcial"),"Encaje parcial","No encaja")) -> Encaje perfecto
A14: 2 | B14: Medición Económica | C14: Formación general / sin equivalente en el catálogo | D14: — | E14: — | F14: No encaja | I14: — | J14: — | K14: — | M14: =IF(OR(F14="Encaje perfecto",K14="Encaje perfecto"),"Encaje perfecto",IF(OR(F14="Encaje parcial",K14="Encaje parcial"),"Encaje parcial","No encaja")) -> No encaja
A15: 2 | B15: Matemáticas Financieras | C15: Formación general / sin equivalente en el catálogo | D15: — | E15: — | F15: No encaja | I15: — | J15: — | K15: — | M15: =IF(OR(F15="Encaje perfecto",K15="Encaje perfecto"),"Encaje perfecto",IF(OR(F15="Encaje parcial",K15="Encaje parcial"),"Encaje parcial","No encaja")) -> No encaja
A16: 2 | B16: Dinámicas de Cadenas de Valor Globales | C16: Formación general / sin equivalente en el catálogo | D16: — | E16: — | F16: No encaja | I16: — | J16: — | K16: — | M16: =IF(OR(F16="Encaje perfecto",K16="Encaje perfecto"),"Encaje perfecto",IF(OR(F16="Encaje parcial",K16="Encaje parcial"),"Encaje parcial","No encaja")) -> No encaja
A17: 2 | B17: Geopolítica | C17: Formación general / sin equivalente en el catálogo | D17: — | E17: — | F17: No encaja | I17: — | J17: — | K17: — | M17: =IF(OR(F17="Encaje perfecto",K17="Encaje perfecto"),"Encaje perfecto",IF(OR(F17="Encaje parcial",K17="Encaje parcial"),"Encaje parcial","No encaja")) -> No encaja
A18: 2 | B18: Investigación de Mercados | C18: Formación general / sin equivalente en el catálogo | D18: — | E18: — | F18: No encaja | I18: — | J18: — | K18: — | M18: =IF(OR(F18="Encaje perfecto",K18="Encaje perfecto"),"Encaje perfecto",IF(OR(F18="Encaje parcial",K18="Encaje parcial"),"Encaje parcial","No encaja")) -> No encaja
... A25: 3 | B25: Taller de Negociación y Argumentación | C25: Formación general / sin equivalente en el catálogo | D25: — | E25: — | F25: No encaja | I25: — | J25: — | K25: — | M25: =IF(OR(F25="Encaje perfecto",K25="Encaje perfecto"),"Encaje perfecto",IF(OR(F25="Encaje parcial",K25="Encaje parcial"),"Encaje parcial","No encaja")) -> No encaja
A26: 3 | B26: Electiva I | C26: Electiva | D26: — | E26: — | F26: No encaja | G26: Contenido variable según la línea elegida; evaluar caso a caso | I26: — | J26: — | K26: — | M26: =IF(OR(F26="Encaje perfecto",K26="Encaje perfecto"),"Encaje perfecto",IF(OR(F26="Encaje parcial",K26="Encaje parcial"),"Encaje parcial","No encaja")) -> No encaja
A27: 3 | B27: Electiva II | C27: Electiva | D27: — | E27: — | F27: No encaja | G27: Contenido variable según la línea elegida; evaluar caso a caso | I27: — | J27: — | K27: — | M27: =IF(OR(F27="Encaje perfecto",K27="Encaje perfecto"),"Encaje perfecto",IF(OR(F27="Encaje parcial",K27="Encaje parcial"),"Encaje parcial","No encaja")) -> No encaja
A28: 4 | B28: Macroeconomía | C28: Economía | D28: — | E28: — | F28: No encaja | I28: — | J28: — | K28: — | M28: =IF(OR(F28="Encaje perfecto",K28="Encaje perfecto"),"Encaje perfecto",IF(OR(F28="Encaje parcial",K28="Encaje parcial"),"Encaje parcial","No encaja")) -> No encaja
A29: 4 | B29: Derecho Laboral y Gestión de Riesgos Organizacionales | C29: Jurídica | D29: — | E29: — | F29: No encaja | I29: — | J29: — | K29: — | M29: =IF(OR(F29="Encaje perfecto",K29="Encaje perfecto"),"Encaje perfecto",IF(OR(F29="Encaje parcial",K29="Encaje parcial"),"Encaje parcial","No encaja")) -> No encaja
A30: 4 | B30: Modelos Organizacionales y Empresariales I | C30: Administración | D30: — | E30: — | F30: No encaja | I30: — | J30: — | K30: — | M30: =IF(OR(F30="Encaje perfecto",K30="Encaje perfecto"),"Encaje perfecto",IF(OR(F30="Encaje parcial",K30="Encaje parcial"),"Encaje parcial","No encaja")) -> No encaja
A31: 4 | B31: Total Quality Management and Innovation | C31: Innovación | D31: — | E31: — | F31: No encaja | I31: — | J31: — | K31: — | M31: =IF(OR(F31="Encaje perfecto",K31="Encaje perfecto"),"Encaje perfecto",IF(OR(F31="Encaje parcial",K31="Encaje parcial"),"Encaje parcial","No encaja")) -> No encaja
A32: 4 | B32: Instituciones Políticas y Competencias Ciudadanas | C32: Formación general / sin equivalente en el catálogo | D32: — | E32: — | F32: No encaja | I32: — | J32: — | K32: — | M32: =IF(OR(F32="Encaje perfecto",K32="Encaje perfecto"),"Encaje perfecto",IF(OR(F32="Encaje parcial",K32="Encaje parcial"),"Encaje parcial","No encaja")) -> No encaja
A33: 4 | B33: Idiomas II | C33: Idiomas | D33: — | E33: — | F33: No encaja | I33: — | J33: — | K33: — | M33: =IF(OR(F33="Encaje perfecto",K33="Encaje perfecto"),"Encaje perfecto",IF(OR(F33="Encaje parcial",K33="Encaje parcial"),"Encaje parcial","No encaja")) -> No encaja
A34: 4 | B34: Bioética y Toma de Decisiones Gerenciales | C34: Formación general / sin equivalente en el catálogo | D34: — | E34: — | F34: No encaja | I34: — | J34: — | K34: — | M34: =IF(OR(F34="Encaje perfecto",K34="Encaje perfecto"),"Encaje perfecto",IF(OR(F34="Encaje parcial",K34="Encaje parcial"),"Encaje parcial","No encaja")) -> No encaja
A35: 4 | B35: Electiva III | C35: Electiva | D35: — | E35: — | F35: No encaja | G35: Contenido variable según la línea elegida; evaluar caso a caso | I35: — | J35: — | K35: — | M35: =IF(OR(F35="Encaje perfecto",K35="Encaje perfecto"),"Encaje perfecto",IF(OR(F35="Encaje parcial",K35="Encaje parcial"),"Encaje parcial","No encaja")) -> No encaja
A36: 5 | B36: Economía Colombiana | C36: Economía | D36: — | E36: — | F36: No encaja | I36: — | J36: — | K36: — | M36: =IF(OR(F36="Encaje perfecto",K36="Encaje perfecto"),"Encaje perfecto",IF(OR(F36="Encaje parcial",K36="Encaje parcial"),"Encaje parcial","No encaja")) -> No encaja
A37: 5 | B37: Finanzas Corporativas | C37: Finanzas | D37: Corbatul | E37: N3-4 | F37: Encaje perfecto | I37: — | J37: — | K37: — | M37: =IF(OR(F37="Encaje perfecto",K37="Encaje perfecto"),"Encaje perfecto",IF(OR(F37="Encaje parcial",K37="Encaje parcial"),"Encaje parcial","No encaja")) -> Encaje perfecto
A38: 5 | B38: Modelos Organizacionales y Empresariales II | C38: Administración | D38: — | E38: — | F38: No encaja | I38: — | J38: — | K38: — | M38: =IF(OR(F38="Encaje perfecto",K38="Encaje perfecto"),"Encaje perfecto",IF(OR(F38="Encaje parcial",K38="Encaje parcial"),"Encaje parcial","No encaja")) -> No encaja
A39: 5 | B39: Production Management | C39: Operaciones | D39: Milk Factory | E39: N5 | F39: Encaje perfecto | I39: — | J39: — | K39: — | M39: =IF(OR(F39="Encaje perfecto",K39="Encaje perfecto"),"Encaje perfecto",IF(OR(F39="Encaje parcial",K39="Encaje parcial"),"Encaje parcial","No encaja")) -> Encaje perfecto
A40: 5 | B40: Formulación y Evaluación de Proyectos | C40: Finanzas/Proyectos | D40: — | E40: — | F40: No encaja | G40: Simulador de evaluación financiera de proyectos (VPN, TIR, flujo de caja proyectado) | I40: — | J40: — | K40: — | M40: =IF(OR(F40="Encaje perfecto",K40="Encaje perfecto"),"Encaje perfecto",IF(OR(F40="Encaje parcial",K40="Encaje parcial"),"Encaje parcial","No encaja")) -> No encaja
A41: 5 | B41: Derecho Internacional de los Negocios | C41: Formación general / sin equivalente en el catálogo | D41: — | E41: — | F41: No encaja | I41: — | J41: — | K41: — | M41: =IF(OR(F41="Encaje perfecto",K41="Encaje perfecto"),"Encaje perfecto",IF(OR(F41="Encaje parcial",K41="Encaje parcial"),"Encaje parcial","No encaja")) -> No encaja
A42: 5 | B42: Idiomas III | C42: Idiomas | D42: — | E42: — | F42: No encaja | I42: — | J42: — | K42: — | M42: =IF(OR(F42="Encaje perfecto",K42="Encaje perfecto"),"Encaje perfecto",IF(OR(F42="Encaje parcial",K42="Encaje parcial"),"Encaje parcial","No encaja")) -> No encaja
A43: 5 | B43: Emprendimiento y Creación de Empresa | C43: Emprendimiento | D43: Fitness Gym | E43: N3-4 | F43: Encaje parcial | I43: SimVenture Validate | J43: Intro (≈N1-2) | K43: Encaje parcial | L43: Cubre el componente de modelos de negocio (Business Model Canvas + validación lean). No cubre estructuras ni diseño organizacional. Validate también sirve como complemento en Emprendimiento y Creación de Empresa. | M43: =IF(OR(F43="Encaje perfecto",K43="Encaje perfecto"),"Encaje perfecto",IF(OR(F43="Encaje parcial",K43="Encaje parcial"),"Encaje parcial","No encaja")) -> Encaje parcial
A44: 5 | B44: Electiva IV | C44: Electiva | D44: — | E44: — | F44: No encaja | G44: Contenido variable según la línea elegida; evaluar caso a caso | I44: — | J44: — | K44: — | M44: =IF(OR(F44="Encaje perfecto",K44="Encaje perfecto"),"Encaje perfecto",IF(OR(F44="Encaje parcial",K44="Encaje parcial"),"Encaje parcial","No encaja")) -> No encaja
A45: 6 | B45: International Economy | C45: Economía | D45: — | E45: — | F45: No encaja | I45: — | J45: — | K45: — | M45: =IF(OR(F45="Encaje perfecto",K45="Encaje perfecto"),"Encaje perfecto",IF(OR(F45="Encaje parcial",K45="Encaje parcial"),"Encaje parcial","No encaja")) -> No encaja
A46: 6 | B46: Finanzas Públicas | C46: Finanzas Públicas / Presupuesto | D46: — | E46: — | F46: No encaja | I46: — | J46: — | K46: — | M46: =IF(OR(F46="Encaje perfecto",K46="Encaje perfecto"),"Encaje perfecto",IF(OR(F46="Encaje parcial",K46="Encaje parcial"),"Encaje parcial","No encaja")) -> No encaja
...

Sheet Adm. Producción y Logística
A1: Administración de Producción y Logística Internacional · Presencial
A2: Semestre | B2: Materia | C2: Área temática | D2: Simulador CompanyGame que encaja | E2: Nivel CG | F2: Grado de ajuste | G2: Tipo de simulador a desarrollar (si no encaja / parcial) | H2: Observación | I2: Otro simulador SNC que encaja | J2: Nivel sugerido | K2: Grado de ajuste (otro SNC) | L2: Observación / uso sugerido (otro SNC) | M2: Cobertura combinada (CG + otro SNC)
A3: 1 | B3: Contabilidad General | C3: Contabilidad | D3: ContaTrainer | E3: N1-2 | F3: Encaje perfecto | I3: — | J3: — | K3: — | M3: =IF(OR(F3="Encaje perfecto",K3="Encaje perfecto"),"Encaje perfecto",IF(OR(F3="Encaje parcial",K3="Encaje parcial"),"Encaje parcial","No encaja")) -> Encaje perfecto
A4: 1 | B4: Principios de Administración y Organizaciones | C4: Administración | D4: T-Shirt | E4: N1-2 | F4: Encaje perfecto | I4: — | J4: — | K4: — | M4: =IF(OR(F4="Encaje perfecto",K4="Encaje perfecto"),"Encaje perfecto",IF(OR(F4="Encaje parcial",K4="Encaje parcial"),"Encaje parcial","No encaja")) -> Encaje perfecto
A5: 1 | B5: Principios de Economía | C5: Formación general / sin equivalente en el catálogo | D5: — | E5: — | F5: No encaja | I5: — | J5: — | K5: — | M5: =IF(OR(F5="Encaje perfecto",K5="Encaje perfecto"),"Encaje perfecto",IF(OR(F5="Encaje parcial",K5="Encaje parcial"),"Encaje parcial","No encaja")) -> No encaja
A6: 1 | B6: Fundamentos de las Finanzas Empresariales | C6: Finanzas | D6: — | E6: — | F6: No encaja | M6: =IF(OR(F6="Encaje perfecto",K6="Encaje perfecto"),"Encaje perfecto",IF(OR(F6="Encaje parcial",K6="Encaje parcial"),"Encaje parcial","No encaja")) -> No encaja
A7: 1 | B7: Logística Internacional | C7: Formación general / sin equivalente en el catálogo | D7: — | E7: — | F7: No encaja | I7: — | J7: — | K7: — | M7: =IF(OR(F7="Encaje perfecto",K7="Encaje perfecto"),"Encaje perfecto",IF(OR(F7="Encaje parcial",K7="Encaje parcial"),"Encaje parcial","No encaja")) -> No encaja
A8: 1 | B8: Teoría de los Negocios Internacionales | C8: Internacional | D8: — | E8: — | F8: No encaja | I8: — | J8: — | K8: — | M8: =IF(OR(F8="Encaje perfecto",K8="Encaje perfecto"),"Encaje perfecto",IF(OR(F8="Encaje parcial",K8="Encaje parcial"),"Encaje parcial","No encaja")) -> No encaja
A9: 1 | B9: Fundamentos de Marketing y Transformación Digital | C9: Marketing | D9: CoffeeTime | E9: N1-2 | F9: Encaje parcial | I9: — | J9: — | K9: — | M9: =IF(OR(F9="Encaje perfecto",K9="Encaje perfecto"),"Encaje perfecto",IF(OR(F9="Encaje parcial",K9="Encaje parcial"),"Encaje parcial","No encaja")) -> Encaje parcial
A10: 1 | B10: Responsabilidad Social Empresarial | C10: Sostenibilidad | D10: — | E10: — | F10: No encaja | I10: — | J10: — | K10: — | M10: =IF(OR(F10="Encaje perfecto",K10="Encaje perfecto"),"Encaje perfecto",IF(OR(F10="Encaje parcial",K10="Encaje parcial"),"Encaje parcial","No encaja")) -> No encaja
A11: 1 | B11: Pensamiento Crítico y Comunicación Efectiva | C11: Formación general / sin equivalente en el catálogo | D11: — | E11: — | F11: No encaja | I11: — | J11: — | K11: — | M11: =IF(OR(F11="Encaje perfecto",K11="Encaje perfecto"),"Encaje perfecto",IF(OR(F11="Encaje parcial",K11="Encaje parcial"),"Encaje parcial","No encaja")) -> No encaja
A12: 2 | B12: Contabilidad de Costos | C12: Formación general / sin equivalente en el catálogo | D12: — | E12: — | F12: No encaja | I12: — | J12: — | K12: — | M12: =IF(OR(F12="Encaje perfecto",K12="Encaje perfecto"),"Encaje perfecto",IF(OR(F12="Encaje parcial",K12="Encaje parcial"),"Encaje parcial","No encaja")) -> No encaja
A13: 2 | B13: Procesos Administrativos | C13: Administración | D13: Energy&Co | E13: N1-2 | F13: Encaje perfecto | I13: — | J13: — | K13: — | M13: =IF(OR(F13="Encaje perfecto",K13="Encaje perfecto"),"Encaje perfecto",IF(OR(F13="Encaje parcial",K13="Encaje parcial"),"Encaje parcial","No encaja")) -> Encaje perfecto
A14: 2 | B14: Medición Económica | C14: Formación general / sin equivalente en el catálogo | D14: — | E14: — | F14: No encaja | I14: — | J14: — | K14: — | M14: =IF(OR(F14="Encaje perfecto",K14="Encaje perfecto"),"Encaje perfecto",IF(OR(F14="Encaje parcial",K14="Encaje parcial"),"Encaje parcial","No encaja")) -> No encaja
A15: 2 | B15: Matemáticas Financieras | C15: Formación general / sin equivalente en el catálogo | D15: — | E15: — | F15: No encaja | I15: — | J15: — | K15: — | M15: =IF(OR(F15="Encaje perfecto",K15="Encaje perfecto"),"Encaje perfecto",IF(OR(F15="Encaje parcial",K15="Encaje parcial"),"Encaje parcial","No encaja")) -> No encaja
A16: 2 | B16: Dinámicas de Cadenas de Valor Globales | C16: Formación general / sin equivalente en el catálogo | D16: — | E16: — | F16: No encaja | I16: — | J16: — | K16: — | M16: =IF(OR(F16="Encaje perfecto",K16="Encaje perfecto"),"Encaje perfecto",IF(OR(F16="Encaje parcial",K16="Encaje parcial"),"Encaje parcial","No encaja")) -> No encaja
A17: 2 | B17: Geopolítica | C17: Formación general / sin equivalente en el catálogo | D17: — | E17: — | F17: No encaja | I17: — | J17: — | K17: — | M17: =IF(OR(F17="Encaje perfecto",K17="Encaje perfecto"),"Encaje perfecto",IF(OR(F17="Encaje parcial",K17="Encaje parcial"),"Encaje parcial","No encaja")) -> No encaja
A18: 2 | B18: Investigación de Mercados | C18: Formación general / sin equivalente en el catálogo | D18: — | E18: — | F18: No encaja | I18: — | J18: — | K18: — | M18: =IF(OR(F18="Encaje perfecto",K18="Encaje perfecto"),"Encaje perfecto",IF(OR(F18="Encaje parcial",K18="Encaje parcial"),"Encaje parcial","No encaja")) -> No encaja
... A27: 3 | B27: Taller de Negociación y Argumentación | C27: Formación general / sin equivalente en el catálogo | D27: — | E27: — | F27: No encaja | I27: — | J27: — | K27: — | M27: =IF(OR(F27="Encaje perfecto",K27="Encaje perfecto"),"Encaje perfecto",IF(OR(F27="Encaje parcial",K27="Encaje parcial"),"Encaje parcial","No encaja")) -> No encaja
A28: 3 | B28: Electiva I | C28: Electiva | D28: — | E28: — | F28: No encaja | G28: Contenido variable según la línea elegida; evaluar caso a caso | I28: — | J28: — | K28: — | M28: =IF(OR(F28="Encaje perfecto",K28="Encaje perfecto"),"Encaje perfecto",IF(OR(F28="Encaje parcial",K28="Encaje parcial"),"Encaje parcial","No encaja")) -> No encaja
A29: 3 | B29: Electiva II | C29: Electiva | D29: — | E29: — | F29: No encaja | G29: Contenido variable según la línea elegida; evaluar caso a caso | I29: — | J29: — | K29: — | M29: =IF(OR(F29="Encaje perfecto",K29="Encaje perfecto"),"Encaje perfecto",IF(OR(F29="Encaje parcial",K29="Encaje parcial"),"Encaje parcial","No encaja")) -> No encaja
A30: 4 | B30: Total Quality Management and Innovation | C30: Innovación | D30: — | E30: — | F30: No encaja | M30: =IF(OR(F30="Encaje perfecto",K30="Encaje perfecto"),"Encaje perfecto",IF(OR(F30="Encaje parcial",K30="Encaje parcial"),"Encaje parcial","No encaja")) -> No encaja
A31: 4 | B31: Operación Logística de Producción | C31: Logística | D31: — | E31: — | F31: No encaja | I31: — | J31: — | K31: — | M31: =IF(OR(F31="Encaje perfecto",K31="Encaje perfecto"),"Encaje perfecto",IF(OR(F31="Encaje parcial",K31="Encaje parcial"),"Encaje parcial","No encaja")) -> No encaja
A32: 4 | B32: Tecnología de la Manipulación en Operaciones | C32: Logística (teoría) | D32: — | E32: — | F32: No encaja | I32: — | J32: — | K32: — | M32: =IF(OR(F32="Encaje perfecto",K32="Encaje perfecto"),"Encaje perfecto",IF(OR(F32="Encaje parcial",K32="Encaje parcial"),"Encaje parcial","No encaja")) -> No encaja
A33: 4 | B33: Recursos Humanos y Desarrollo Organizacional | C33: Talento Humano | D33: — | E33: — | F33: No encaja | I33: — | J33: — | K33: — | M33: =IF(OR(F33="Encaje perfecto",K33="Encaje perfecto"),"Encaje perfecto",IF(OR(F33="Encaje parcial",K33="Encaje parcial"),"Encaje parcial","No encaja")) -> No encaja
A34: 4 | B34: Instituciones Políticas y Competencias Ciudadanas | C34: Formación general / sin equivalente en el catálogo | D34: — | E34: — | F34: No encaja | I34: — | J34: — | K34: — | M34: =IF(OR(F34="Encaje perfecto",K34="Encaje perfecto"),"Encaje perfecto",IF(OR(F34="Encaje parcial",K34="Encaje parcial"),"Encaje parcial","No encaja")) -> No encaja
A35: 4 | B35: Idiomas II | C35: Idiomas | D35: — | E35: — | F35: No encaja | I35: — | J35: — | K35: — | M35: =IF(OR(F35="Encaje perfecto",K35="Encaje perfecto"),"Encaje perfecto",IF(OR(F35="Encaje parcial",K35="Encaje parcial"),"Encaje parcial","No encaja")) -> No encaja
A36: 4 | B36: Bioética y Toma de Decisiones Gerenciales | C36: Formación general / sin equivalente en el catálogo | D36: — | E36: — | F36: No encaja | I36: — | J36: — | K36: — | M36: =IF(OR(F36="Encaje perfecto",K36="Encaje perfecto"),"Encaje perfecto",IF(OR(F36="Encaje parcial",K36="Encaje parcial"),"Encaje parcial","No encaja")) -> No encaja
A37: 4 | B37: Electiva III | C37: Electiva | D37: — | E37: — | F37: No encaja | G37: Contenido variable según la línea elegida; evaluar caso a caso | I37: — | J37: — | K37: — | M37: =IF(OR(F37="Encaje perfecto",K37="Encaje perfecto"),"Encaje perfecto",IF(OR(F37="Encaje parcial",K37="Encaje parcial"),"Encaje parcial","No encaja")) -> No encaja
A38: 5 | B38: Planeación Estratégica de Operaciones | C38: Operaciones | D38: Milk Factory | E38: N5 | F38: Encaje perfecto | I38: — | J38: — | K38: — | M38: =IF(OR(F38="Encaje perfecto",K38="Encaje perfecto"),"Encaje perfecto",IF(OR(F38="Encaje parcial",K38="Encaje parcial"),"Encaje parcial","No encaja")) -> Encaje perfecto
A39: 5 | B39: Gestión de Modos y Medios de Transporte | C39: Logística (teoría) | D39: — | E39: — | F39: No encaja | I39: — | J39: — | K39: — | M39: =IF(OR(F39="Encaje perfecto",K39="Encaje perfecto"),"Encaje perfecto",IF(OR(F39="Encaje parcial",K39="Encaje parcial"),"Encaje parcial","No encaja")) -> No encaja
A40: 5 | B40: Diseño y Gestión de Sistemas Logísticos | C40: Logística (teoría) | D40: — | E40: — | F40: No encaja | I40: — | J40: — | K40: — | M40: =IF(OR(F40="Encaje perfecto",K40="Encaje perfecto"),"Encaje perfecto",IF(OR(F40="Encaje parcial",K40="Encaje parcial"),"Encaje parcial","No encaja")) -> No encaja
A41: 5 | B41: Formulación y Evaluación de Proyectos | C41: Finanzas/Proyectos | D41: — | E41: — | F41: No encaja | G41: Simulador de evaluación financiera de proyectos (VPN, TIR, flujo de caja proyectado) | I41: — | J41: — | K41: — | M41: =IF(OR(F41="Encaje perfecto",K41="Encaje perfecto"),"Encaje perfecto",IF(OR(F41="Encaje parcial",K41="Encaje parcial"),"Encaje parcial","No encaja")) -> No encaja
A42: 5 | B42: Derecho Internacional de los Negocios | C42: Formación general / sin equivalente en el catálogo | D42: — | E42: — | F42: No encaja | I42: — | J42: — | K42: — | M42: =IF(OR(F42="Encaje perfecto",K42="Encaje perfecto"),"Encaje perfecto",IF(OR(F42="Encaje parcial",K42="Encaje parcial"),"Encaje parcial","No encaja")) -> No encaja
A43: 5 | B43: Idiomas III | C43: Idiomas | D43: — | E43: — | F43: No encaja | M43: =IF(OR(F43="Encaje perfecto",K43="Encaje perfecto"),"Encaje perfecto",IF(OR(F43="Encaje parcial",K43="Encaje parcial"),"Encaje parcial","No encaja")) -> No encaja
A44: 5 | B44: Emprendimiento y Creación de Empresa | C44: Emprendimiento | D44: Fitness Gym | E44: N3-4 | F44: Encaje parcial | I44: SimVenture Validate | J44: Intro (≈N1-2) | K44: Encaje parcial | L44: Cubre el componente de innovación (ideación y validación de nuevas propuestas de valor). No cubre gestión de calidad total. Validate también sirve como complemento en Emprendimiento. | M44: =IF(OR(F44="Encaje perfecto",K44="Encaje perfecto"),"Encaje perfecto",IF(OR(F44="Encaje parcial",K44="Encaje parcial"),"Encaje parcial","No encaja")) -> Encaje parcial
A45: 5 | B45: Electiva IV | C45: Electiva | D45: — | E45: — | F45: No encaja | G45: Contenido variable según la línea elegida; evaluar caso a caso | I45: — | J45: — | K45: — | M45: =IF(OR(F45="Encaje perfecto",K45="Encaje perfecto"),"Encaje perfecto",IF(OR(F45="Encaje parcial",K45="Encaje parcial"),"Encaje parcial","No encaja")) -> No encaja
A46: 6 | B46: Supply Chain Management | C46: Internacional | D46: Global 2020 | E46: N6-7 | F46: Encaje perfecto | I46: — | J46: — | K46: — | M46: =IF(OR(F46="Encaje perfecto",K46="Encaje perfecto"),"Encaje perfecto",IF(OR(F46="Encaje parcial",K46="Encaje parcial"),"Encaje parcial","No encaja")) -> Encaje perfecto
A47: 6 | B47: Operaciones Logísticas del Retorno | C47: Logística (teoría) | D47: — | E47: — | F47: No encaja | I47: — | J47: — | K47: — | M47: =IF(OR(F47="Encaje perfecto",K47="Encaje perfecto"),"Encaje perfecto",IF(OR(F47="Encaje parcial",K47="Encaje parcial"),"Encaje parcial","No encaja")) -> No encaja
A48: 6 | B48: Sistemas de Información Logísticos | C48: Logística (teoría) | D48: — | E48: — | F48: No encaja | I48: — | J48: — | K48: — | M48: =IF(OR(F48="Encaje perfecto",K48="Encaje perfecto"),"Encaje perfecto",IF(OR(F48="Encaje parcial",K48="Encaje parcial"),"Encaje parcial","No encaja")) -> No encaja
...

Sheet Adm. Negocios Sostenibles
A1: Administración de Negocios Sostenibles · Virtual
A2: Semestre | B2: Materia | C2: Área temática | D2: Simulador CompanyGame que encaja | E2: Nivel CG | F2: Grado de ajuste | G2: Tipo de simulador a desarrollar (si no encaja / parcial) | H2: Observación | I2: Otro simulador SNC que encaja | J2: Nivel sugerido | K2: Grado de ajuste (otro SNC) | L2: Observación / uso sugerido (otro SNC) | M2: Cobertura combinada (CG + otro SNC)
A3: 1 | B3: Contabilidad General | C3: Contabilidad | D3: ContaTrainer | E3: N1-2 | F3: Encaje perfecto | I3: — | J3: — | K3: — | M3: =IF(OR(F3="Encaje perfecto",K3="Encaje perfecto"),"Encaje perfecto",IF(OR(F3="Encaje parcial",K3="Encaje parcial"),"Encaje parcial","No encaja")) -> Encaje perfecto
A4: 1 | B4: Principios de Administración y Organizaciones | C4: Administración | D4: T-Shirt | E4: N1-2 | F4: Encaje perfecto | I4: — | J4: — | K4: — | M4: =IF(OR(F4="Encaje perfecto",K4="Encaje perfecto"),"Encaje perfecto",IF(OR(F4="Encaje parcial",K4="Encaje parcial"),"Encaje parcial","No encaja")) -> Encaje perfecto
A5: 1 | B5: Principios de Economía | C5: Formación general / sin equivalente en el catálogo | D5: — | E5: — | F5: No encaja | I5: — | J5: — | K5: — | M5: =IF(OR(F5="Encaje perfecto",K5="Encaje perfecto"),"Encaje perfecto",IF(OR(F5="Encaje parcial",K5="Encaje parcial"),"Encaje parcial","No encaja")) -> No encaja
A6: 1 | B6: Fundamentos de las Finanzas Empresariales | C6: Finanzas | D6: — | E6: — | F6: No encaja | M6: =IF(OR(F6="Encaje perfecto",K6="Encaje perfecto"),"Encaje perfecto",IF(OR(F6="Encaje parcial",K6="Encaje parcial"),"Encaje parcial","No encaja")) -> No encaja
A7: 1 | B7: Logística Internacional | C7: Formación general / sin equivalente en el catálogo | D7: — | E7: — | F7: No encaja | I7: — | J7: — | K7: — | M7: =IF(OR(F7="Encaje perfecto",K7="Encaje perfecto"),"Encaje perfecto",IF(OR(F7="Encaje parcial",K7="Encaje parcial"),"Encaje parcial","No encaja")) -> No encaja
A8: 1 | B8: Teoría de los Negocios Internacionales | C8: Internacional | D8: Sunny Day | E8: N1-2 | F8: Encaje perfecto | I8: — | J8: — | K8: — | M8: =IF(OR(F8="Encaje perfecto",K8="Encaje perfecto"),"Encaje perfecto",IF(OR(F8="Encaje parcial",K8="Encaje parcial"),"Encaje parcial","No encaja")) -> Encaje perfecto
A9: 1 | B9: Fundamentos de Marketing y Transformación Digital | C9: Marketing | D9: CoffeeTime | E9: N1-2 | F9: Encaje parcial | I9: — | J9: — | K9: — | M9: =IF(OR(F9="Encaje perfecto",K9="Encaje perfecto"),"Encaje perfecto",IF(OR(F9="Encaje parcial",K9="Encaje parcial"),"Encaje parcial","No encaja")) -> Encaje parcial
A10: 1 | B10: Responsabilidad Social Empresarial | C10: Sostenibilidad | D10: — | E10: — | F10: No encaja | I10: — | J10: — | K10: — | M10: =IF(OR(F10="Encaje perfecto",K10="Encaje perfecto"),"Encaje perfecto",IF(OR(F10="Encaje parcial",K10="Encaje parcial"),"Encaje parcial","No encaja")) -> No encaja
A11: 1 | B11: Pensamiento Crítico y Comunicación Efectiva | C11: Formación general / sin equivalente en el catálogo | D11: — | E11: — | F11: No encaja | I11: — | J11: — | K11: — | M11: =IF(OR(F11="Encaje perfecto",K11="Encaje perfecto"),"Encaje perfecto",IF(OR(F11="Encaje parcial",K11="Encaje parcial"),"Encaje parcial","No encaja")) -> No encaja
A12: 2 | B12: Contabilidad de Costos | C12: Formación general / sin equivalente en el catálogo | D12: — | E12: — | F12: No encaja | I12: — | J12: — | K12: — | M12: =IF(OR(F12="Encaje perfecto",K12="Encaje perfecto"),"Encaje perfecto",IF(OR(F12="Encaje parcial",K12="Encaje parcial"),"Encaje parcial","No encaja")) -> No encaja
A13: 2 | B13: Procesos Administrativos | C13: Administración | D13: Energy&Co | E13: N1-2 | F13: Encaje perfecto | I13: — | J13: — | K13: — | M13: =IF(OR(F13="Encaje perfecto",K13="Encaje perfecto"),"Encaje perfecto",IF(OR(F13="Encaje parcial",K13="Encaje parcial"),"Encaje parcial","No encaja")) -> Encaje perfecto
A14: 2 | B14: Medición Económica | C14: Formación general / sin equivalente en el catálogo | D14: — | E14: — | F14: No encaja | I14: — | J14: — | K14: — | M14: =IF(OR(F14="Encaje perfecto",K14="Encaje perfecto"),"Encaje perfecto",IF(OR(F14="Encaje parcial",K14="Encaje parcial"),"Encaje parcial","No encaja")) -> No encaja
A15: 2 | B15: Matemáticas Financieras | C15: Formación general / sin equivalente en el catálogo | D15: — | E15: — | F15: No encaja | I15: — | J15: — | K15: — | M15: =IF(OR(F15="Encaje perfecto",K15="Encaje perfecto"),"Encaje perfecto",IF(OR(F15="Encaje parcial",K15="Encaje parcial"),"Encaje parcial","No encaja")) -> No encaja
A16: 2 | B16: Dinámicas de Cadenas de Valor Globales | C16: Formación general / sin equivalente en el catálogo | D16: — | E16: — | F16: No encaja | I16: — | J16: — | K16: — | M16: =IF(OR(F16="Encaje perfecto",K16="Encaje perfecto"),"Encaje perfecto",IF(OR(F16="Encaje parcial",K16="Encaje parcial"),"Encaje parcial","No encaja")) -> No encaja
A17: 2 | B17: Geopolítica | C17: Formación general / sin equivalente en el catálogo | D17: — | E17: — | F17: No encaja | I17: — | J17: — | K17: — | M17: =IF(OR(F17="Encaje perfecto",K17="Encaje perfecto"),"Encaje perfecto",IF(OR(F17="Encaje parcial",K17="Encaje parcial"),"Encaje parcial","No encaja")) -> No encaja
